2023-06-13 14:59:54,124 INFO    StreamThr :22192 [internal.py:wandb_internal():86] W&B internal server running at pid: 22192, started at: 2023-06-13 14:59:54.124320
2023-06-13 14:59:54,125 DEBUG   HandlerThread:22192 [handler.py:handle_request():144] handle_request: status
2023-06-13 14:59:54,142 INFO    WriterThread:22192 [datastore.py:open_for_write():85] open: ./wandb/run-20230613_145954-5a6s6znd/run-5a6s6znd.wandb
2023-06-13 14:59:54,143 DEBUG   SenderThread:22192 [sender.py:send():369] send: header
2023-06-13 14:59:54,146 DEBUG   SenderThread:22192 [sender.py:send():369] send: run
2023-06-13 14:59:54,147 INFO    SenderThread:22192 [sender.py:_maybe_setup_resume():737] checking resume status for wandb/CycleTraining/5a6s6znd
2023-06-13 14:59:54,574 ERROR   SenderThread:22192 [internal_api.py:execute():323] 403 response executing GraphQL.
2023-06-13 14:59:54,574 ERROR   SenderThread:22192 [internal_api.py:execute():324] {"errors":[{"message":"permission denied","path":["upsertBucket"],"extensions":{"code":"PERMISSION_ERROR"}}],"data":{"upsertBucket":null}}
2023-06-13 14:59:54,574 ERROR   SenderThread:22192 [sender.py:send_run():955] It appears that you do not have permission to access the requested resource. Please reach out to the project owner to grant you access. If you have the correct permissions, verify that there are no issues with your networking setup.(Error 403: Forbidden)
Traceback (most recent call last):
  File "/home/liam/anaconda3/envs/cycle-lightning/lib/python3.10/site-packages/wandb/sdk/lib/retry.py", line 131, in __call__
    result = self._call_fn(*args, **kwargs)
  File "/home/liam/anaconda3/envs/cycle-lightning/lib/python3.10/site-packages/wandb/sdk/internal/internal_api.py", line 320, in execute
    return self.client.execute(*args, **kwargs)  # type: ignore
  File "/home/liam/anaconda3/envs/cycle-lightning/lib/python3.10/site-packages/wandb/vendor/gql-0.2.0/wandb_gql/client.py", line 52, in execute
    result = self._get_result(document, *args, **kwargs)
  File "/home/liam/anaconda3/envs/cycle-lightning/lib/python3.10/site-packages/wandb/vendor/gql-0.2.0/wandb_gql/client.py", line 60, in _get_result
    return self.transport.execute(document, *args, **kwargs)
  File "/home/liam/anaconda3/envs/cycle-lightning/lib/python3.10/site-packages/wandb/sdk/lib/gql_request.py", line 56, in execute
    request.raise_for_status()
  File "/home/liam/anaconda3/envs/cycle-lightning/lib/python3.10/site-packages/requests/models.py", line 1021, in raise_for_status
    raise HTTPError(http_error_msg, response=self)
requests.exceptions.HTTPError: 403 Client Error: Forbidden for url: https://api.wandb.ai/graphql

During handling of the above exception, another exception occurred:

Traceback (most recent call last):
  File "/home/liam/anaconda3/envs/cycle-lightning/lib/python3.10/site-packages/wandb/sdk/internal/sender.py", line 953, in send_run
    self._init_run(run, config_value_dict)
  File "/home/liam/anaconda3/envs/cycle-lightning/lib/python3.10/site-packages/wandb/sdk/internal/sender.py", line 991, in _init_run
    server_run, inserted, server_messages = self._api.upsert_run(
  File "/home/liam/anaconda3/envs/cycle-lightning/lib/python3.10/site-packages/wandb/apis/normalize.py", line 73, in wrapper
    raise err
  File "/home/liam/anaconda3/envs/cycle-lightning/lib/python3.10/site-packages/wandb/apis/normalize.py", line 41, in wrapper
    return func(*args, **kwargs)
  File "/home/liam/anaconda3/envs/cycle-lightning/lib/python3.10/site-packages/wandb/sdk/internal/internal_api.py", line 1727, in upsert_run
    response = self.gql(
  File "/home/liam/anaconda3/envs/cycle-lightning/lib/python3.10/site-packages/wandb/sdk/internal/internal_api.py", line 292, in gql
    ret = self._retry_gql(
  File "/home/liam/anaconda3/envs/cycle-lightning/lib/python3.10/site-packages/wandb/sdk/lib/retry.py", line 147, in __call__
    retry_timedelta_triggered = check_retry_fn(e)
  File "/home/liam/anaconda3/envs/cycle-lightning/lib/python3.10/site-packages/wandb/util.py", line 908, in check_retry_fn
    return fallback_retry_fn(e)
  File "/home/liam/anaconda3/envs/cycle-lightning/lib/python3.10/site-packages/wandb/util.py", line 850, in no_retry_auth
    raise CommError(
wandb.errors.CommError: It appears that you do not have permission to access the requested resource. Please reach out to the project owner to grant you access. If you have the correct permissions, verify that there are no issues with your networking setup.(Error 403: Forbidden)
2023-06-13 14:59:54,657 DEBUG   HandlerThread:22192 [handler.py:handle_request():144] handle_request: shutdown
2023-06-13 14:59:54,657 INFO    HandlerThread:22192 [handler.py:finish():854] shutting down handler
2023-06-13 14:59:55,146 INFO    WriterThread:22192 [datastore.py:close():298] close: ./wandb/run-20230613_145954-5a6s6znd/run-5a6s6znd.wandb
2023-06-13 14:59:55,576 INFO    SenderThread:22192 [sender.py:finish():1526] shutting down sender
